[2025-08-08T12:28:38.575+0000] {local_task_job_runner.py:120} INFO - ::group::Pre task execution logs
[2025-08-08T12:28:38.623+0000] {taskinstance.py:2076} INFO - Dependencies all met for dep_context=non-requeueable deps ti=<TaskInstance: jobs_crawler_dag.upload_jobs_to_minio manual__2025-08-08T12:26:09.298420+00:00 [queued]>
[2025-08-08T12:28:38.631+0000] {taskinstance.py:2076} INFO - Dependencies all met for dep_context=requeueable deps ti=<TaskInstance: jobs_crawler_dag.upload_jobs_to_minio manual__2025-08-08T12:26:09.298420+00:00 [queued]>
[2025-08-08T12:28:38.631+0000] {taskinstance.py:2306} INFO - Starting attempt 2 of 2
[2025-08-08T12:28:38.643+0000] {taskinstance.py:2330} INFO - Executing <Task(PythonOperator): upload_jobs_to_minio> on 2025-08-08 12:26:09.298420+00:00
[2025-08-08T12:28:38.671+0000] {standard_task_runner.py:63} INFO - Started process 111 to run task
[2025-08-08T12:28:38.674+0000] {standard_task_runner.py:90} INFO - Running: ['***', 'tasks', 'run', 'jobs_crawler_dag', 'upload_jobs_to_minio', 'manual__2025-08-08T12:26:09.298420+00:00', '--job-id', '5', '--raw', '--subdir', 'DAGS_FOLDER/crawl_jobs_dag.py', '--cfg-path', '/tmp/tmpv0nv262j']
[2025-08-08T12:28:38.678+0000] {standard_task_runner.py:91} INFO - Job 5: Subtask upload_jobs_to_minio
[2025-08-08T12:28:38.741+0000] {task_command.py:426} INFO - Running <TaskInstance: jobs_crawler_dag.upload_jobs_to_minio manual__2025-08-08T12:26:09.298420+00:00 [running]> on host 7c97c18d1ccf
[2025-08-08T12:28:38.837+0000] {taskinstance.py:2648} INFO - Exporting env vars: AIRFLOW_CTX_DAG_OWNER='***' AIRFLOW_CTX_DAG_ID='jobs_crawler_dag' AIRFLOW_CTX_TASK_ID='upload_jobs_to_minio' AIRFLOW_CTX_EXECUTION_DATE='2025-08-08T12:26:09.298420+00:00' AIRFLOW_CTX_TRY_NUMBER='2' AIRFLOW_CTX_DAG_RUN_ID='manual__2025-08-08T12:26:09.298420+00:00'
[2025-08-08T12:28:38.838+0000] {taskinstance.py:430} INFO - ::endgroup::
[2025-08-08T12:28:39.706+0000] {taskinstance.py:441} INFO - ::group::Post task execution logs
[2025-08-08T12:28:39.710+0000] {taskinstance.py:2905} ERROR - Task failed with exception
Traceback (most recent call last):
  File "/home/airflow/.local/lib/python3.11/site-packages/airflow/models/taskinstance.py", line 465, in _execute_task
    result = _execute_callable(context=context, **execute_callable_kwargs)
             ^^^^^^^^^^^^^^^^^^^^^^^^^^^^^^^^^^^^^^^^^^^^^^^^^^^^^^^^^^^^^
  File "/home/airflow/.local/lib/python3.11/site-packages/airflow/models/taskinstance.py", line 432, in _execute_callable
    return execute_callable(context=context, **execute_callable_kwargs)
           ^^^^^^^^^^^^^^^^^^^^^^^^^^^^^^^^^^^^^^^^^^^^^^^^^^^^^^^^^^^^
  File "/home/airflow/.local/lib/python3.11/site-packages/airflow/models/baseoperator.py", line 400, in wrapper
    return func(self, *args, **kwargs)
           ^^^^^^^^^^^^^^^^^^^^^^^^^^^
  File "/home/airflow/.local/lib/python3.11/site-packages/airflow/operators/python.py", line 235, in execute
    return_value = self.execute_callable()
                   ^^^^^^^^^^^^^^^^^^^^^^^
  File "/home/airflow/.local/lib/python3.11/site-packages/airflow/operators/python.py", line 252, in execute_callable
    return self.python_callable(*self.op_args, **self.op_kwargs)
           ^^^^^^^^^^^^^^^^^^^^^^^^^^^^^^^^^^^^^^^^^^^^^^^^^^^^^
  File "/opt/airflow/spark/src/elt/load/upload_jobs_to_gcs.py", line 33, in upload_jobs_to_gcs
    blob.upload_from_file(buffer, content_type="application/octet-stream")
  File "/home/airflow/.local/lib/python3.11/site-packages/google/cloud/storage/blob.py", line 2796, in upload_from_file
    self._prep_and_do_upload(
  File "/home/airflow/.local/lib/python3.11/site-packages/google/cloud/storage/blob.py", line 2637, in _prep_and_do_upload
    created_json = self._do_upload(
                   ^^^^^^^^^^^^^^^^
  File "/home/airflow/.local/lib/python3.11/site-packages/google/cloud/storage/blob.py", line 2460, in _do_upload
    response = self._do_resumable_upload(
               ^^^^^^^^^^^^^^^^^^^^^^^^^^
  File "/home/airflow/.local/lib/python3.11/site-packages/google/cloud/storage/blob.py", line 2278, in _do_resumable_upload
    upload, transport = self._initiate_resumable_upload(
                        ^^^^^^^^^^^^^^^^^^^^^^^^^^^^^^^^
  File "/home/airflow/.local/lib/python3.11/site-packages/google/cloud/storage/blob.py", line 2152, in _initiate_resumable_upload
    upload.initiate(
  File "/home/airflow/.local/lib/python3.11/site-packages/google/resumable_media/requests/upload.py", line 420, in initiate
    return _request_helpers.wait_and_retry(
           ^^^^^^^^^^^^^^^^^^^^^^^^^^^^^^^^
  File "/home/airflow/.local/lib/python3.11/site-packages/google/resumable_media/requests/_request_helpers.py", line 155, in wait_and_retry
    response = func()
               ^^^^^^
  File "/home/airflow/.local/lib/python3.11/site-packages/google/resumable_media/requests/upload.py", line 412, in retriable_request
    result = transport.request(
             ^^^^^^^^^^^^^^^^^^
  File "/home/airflow/.local/lib/python3.11/site-packages/google/auth/transport/requests.py", line 537, in request
    self.credentials.before_request(auth_request, method, url, request_headers)
  File "/home/airflow/.local/lib/python3.11/site-packages/google/auth/credentials.py", line 230, in before_request
    self._blocking_refresh(request)
  File "/home/airflow/.local/lib/python3.11/site-packages/google/auth/credentials.py", line 193, in _blocking_refresh
    self.refresh(request)
  File "/home/airflow/.local/lib/python3.11/site-packages/google/oauth2/service_account.py", line 445, in refresh
    access_token, expiry, _ = _client.jwt_grant(
                              ^^^^^^^^^^^^^^^^^^
  File "/home/airflow/.local/lib/python3.11/site-packages/google/oauth2/_client.py", line 308, in jwt_grant
    response_data = _token_endpoint_request(
                    ^^^^^^^^^^^^^^^^^^^^^^^^
  File "/home/airflow/.local/lib/python3.11/site-packages/google/oauth2/_client.py", line 279, in _token_endpoint_request
    _handle_error_response(response_data, retryable_error)
  File "/home/airflow/.local/lib/python3.11/site-packages/google/oauth2/_client.py", line 72, in _handle_error_response
    raise exceptions.RefreshError(
google.auth.exceptions.RefreshError: ('invalid_grant: Invalid JWT Signature.', {'error': 'invalid_grant', 'error_description': 'Invalid JWT Signature.'})
[2025-08-08T12:28:39.813+0000] {taskinstance.py:1206} INFO - Marking task as FAILED. dag_id=jobs_crawler_dag, task_id=upload_jobs_to_minio, run_id=manual__2025-08-08T12:26:09.298420+00:00, execution_date=20250808T122609, start_date=20250808T122838, end_date=20250808T122839
[2025-08-08T12:28:39.850+0000] {standard_task_runner.py:110} ERROR - Failed to execute job 5 for task upload_jobs_to_minio (('invalid_grant: Invalid JWT Signature.', {'error': 'invalid_grant', 'error_description': 'Invalid JWT Signature.'}); 111)
[2025-08-08T12:28:39.893+0000] {local_task_job_runner.py:240} INFO - Task exited with return code 1
[2025-08-08T12:28:39.917+0000] {taskinstance.py:3498} INFO - 0 downstream tasks scheduled from follow-on schedule check
[2025-08-08T12:28:39.920+0000] {local_task_job_runner.py:222} INFO - ::endgroup::
