[2025-09-09T02:43:16.947+0000] {local_task_job_runner.py:120} INFO - ::group::Pre task execution logs
[2025-09-09T02:43:16.967+0000] {taskinstance.py:2076} INFO - Dependencies all met for dep_context=non-requeueable deps ti=<TaskInstance: jobs_crawler_dag.upload_jobs_to_gcs manual__2025-09-09T02:43:05.827744+00:00 [queued]>
[2025-09-09T02:43:16.974+0000] {taskinstance.py:2076} INFO - Dependencies all met for dep_context=requeueable deps ti=<TaskInstance: jobs_crawler_dag.upload_jobs_to_gcs manual__2025-09-09T02:43:05.827744+00:00 [queued]>
[2025-09-09T02:43:16.974+0000] {taskinstance.py:2306} INFO - Starting attempt 1 of 2
[2025-09-09T02:43:16.990+0000] {taskinstance.py:2330} INFO - Executing <Task(PythonOperator): upload_jobs_to_gcs> on 2025-09-09 02:43:05.827744+00:00
[2025-09-09T02:43:16.994+0000] {standard_task_runner.py:63} INFO - Started process 309 to run task
[2025-09-09T02:43:16.997+0000] {standard_task_runner.py:90} INFO - Running: ['***', 'tasks', 'run', 'jobs_crawler_dag', 'upload_jobs_to_gcs', 'manual__2025-09-09T02:43:05.827744+00:00', '--job-id', '24', '--raw', '--subdir', 'DAGS_FOLDER/crawl_jobs_dag.py', '--cfg-path', '/tmp/tmp5jhuo9_o']
[2025-09-09T02:43:16.999+0000] {standard_task_runner.py:91} INFO - Job 24: Subtask upload_jobs_to_gcs
[2025-09-09T02:43:17.039+0000] {task_command.py:426} INFO - Running <TaskInstance: jobs_crawler_dag.upload_jobs_to_gcs manual__2025-09-09T02:43:05.827744+00:00 [running]> on host c46b67be7e4e
[2025-09-09T02:43:17.108+0000] {taskinstance.py:2648} INFO - Exporting env vars: AIRFLOW_CTX_DAG_OWNER='***' AIRFLOW_CTX_DAG_ID='jobs_crawler_dag' AIRFLOW_CTX_TASK_ID='upload_jobs_to_gcs' AIRFLOW_CTX_EXECUTION_DATE='2025-09-09T02:43:05.827744+00:00' AIRFLOW_CTX_TRY_NUMBER='1' AIRFLOW_CTX_DAG_RUN_ID='manual__2025-09-09T02:43:05.827744+00:00'
[2025-09-09T02:43:17.109+0000] {taskinstance.py:430} INFO - ::endgroup::
[2025-09-09T02:43:17.133+0000] {taskinstance.py:441} INFO - ::group::Post task execution logs
[2025-09-09T02:43:17.134+0000] {taskinstance.py:2905} ERROR - Task failed with exception
Traceback (most recent call last):
  File "/home/airflow/.local/lib/python3.11/site-packages/airflow/models/taskinstance.py", line 465, in _execute_task
    result = _execute_callable(context=context, **execute_callable_kwargs)
             ^^^^^^^^^^^^^^^^^^^^^^^^^^^^^^^^^^^^^^^^^^^^^^^^^^^^^^^^^^^^^
  File "/home/airflow/.local/lib/python3.11/site-packages/airflow/models/taskinstance.py", line 432, in _execute_callable
    return execute_callable(context=context, **execute_callable_kwargs)
           ^^^^^^^^^^^^^^^^^^^^^^^^^^^^^^^^^^^^^^^^^^^^^^^^^^^^^^^^^^^^
  File "/home/airflow/.local/lib/python3.11/site-packages/airflow/models/baseoperator.py", line 400, in wrapper
    return func(self, *args, **kwargs)
           ^^^^^^^^^^^^^^^^^^^^^^^^^^^
  File "/home/airflow/.local/lib/python3.11/site-packages/airflow/operators/python.py", line 235, in execute
    return_value = self.execute_callable()
                   ^^^^^^^^^^^^^^^^^^^^^^^
  File "/home/airflow/.local/lib/python3.11/site-packages/airflow/operators/python.py", line 252, in execute_callable
    return self.python_callable(*self.op_args, **self.op_kwargs)
           ^^^^^^^^^^^^^^^^^^^^^^^^^^^^^^^^^^^^^^^^^^^^^^^^^^^^^
  File "/opt/airflow/spark/src/elt/load/upload_jobs_to_minio.py", line 27, in upload_jobs_to_minio
    ensure_bucket_exists(MINIO_BUCKET)
  File "/opt/airflow/spark/src/elt/load/upload_jobs_to_minio.py", line 23, in ensure_bucket_exists
    s3_client.create_bucket(Bucket=bucket_name)
  File "/home/airflow/.local/lib/python3.11/site-packages/botocore/client.py", line 553, in _api_call
    return self._make_api_call(operation_name, kwargs)
           ^^^^^^^^^^^^^^^^^^^^^^^^^^^^^^^^^^^^^^^^^^^
  File "/home/airflow/.local/lib/python3.11/site-packages/botocore/client.py", line 1009, in _make_api_call
    raise error_class(parsed_response, operation_name)
botocore.exceptions.ClientError: An error occurred (InvalidBucketName) when calling the CreateBucket operation: The specified bucket is not valid.
[2025-09-09T02:43:17.143+0000] {taskinstance.py:1206} INFO - Marking task as UP_FOR_RETRY. dag_id=jobs_crawler_dag, task_id=upload_jobs_to_gcs, run_id=manual__2025-09-09T02:43:05.827744+00:00, execution_date=20250909T024305, start_date=20250909T024316, end_date=20250909T024317
[2025-09-09T02:43:17.151+0000] {standard_task_runner.py:110} ERROR - Failed to execute job 24 for task upload_jobs_to_gcs (An error occurred (InvalidBucketName) when calling the CreateBucket operation: The specified bucket is not valid.; 309)
[2025-09-09T02:43:17.169+0000] {local_task_job_runner.py:240} INFO - Task exited with return code 1
[2025-09-09T02:43:17.181+0000] {taskinstance.py:3498} INFO - 0 downstream tasks scheduled from follow-on schedule check
[2025-09-09T02:43:17.187+0000] {local_task_job_runner.py:222} INFO - ::endgroup::
